<?xml version="1.0"?>
<sdf version="1.7">
  <model name="fanuc_m20i">
    <static>true</static>
    <self_collide>false</self_collide>

    <link name="base_link">
      <inertial>
        <mass>40.0</mass>
        <inertia>
          <ixx>1.0</ixx>
          <iyy>1.0</iyy>
          <izz>1.0</izz>
        </inertia>
      </inertial>
      <visual name="base_visual">
        <geometry>
          <mesh>
            <uri>model://fanuc_m20i/meshes/m20ib25/visual/base_link.stl</uri>
          </mesh>
        </geometry>
        <material>
          <ambient>0.2784313725490196 0.2784313725490196 0.2784313725490196 1.0</ambient>
          <diffuse>0.2784313725490196 0.2784313725490196 0.2784313725490196 1.0</diffuse>
        </material>
      </visual>
      <collision name="base_collision">
        <geometry>
          <mesh>
            <uri>model://fanuc_m20i/meshes/m20ib25/collision/base_link.stl</uri>
          </mesh>
        </geometry>
      </collision>
    </link>

    <link name="link_1">
      <inertial>
        <mass>20.0</mass>
        <inertia>
          <ixx>1.0</ixx>
          <iyy>1.0</iyy>
          <izz>1.0</izz>
        </inertia>
      </inertial>
      <visual name="link_1_visual">
        <geometry>
          <mesh>
            <uri>model://fanuc_m20i/meshes/m20ib25/visual/link_1.stl</uri>
          </mesh>
        </geometry>
        <material>
          <ambient>0.96 0.76 0.13 1.0</ambient>
          <diffuse>0.96 0.76 0.13 1.0</diffuse>
        </material>
      </visual>
      <collision name="link_1_collision">
        <geometry>
          <mesh>
            <uri>model://fanuc_m20i/meshes/m20ib25/collision/link_1.stl</uri>
          </mesh>
        </geometry>
      </collision>
    </link>

    <link name="link_2">
      <inertial>
        <mass>18.0</mass>
        <inertia>
          <ixx>1.0</ixx>
          <iyy>1.0</iyy>
          <izz>1.0</izz>
        </inertia>
      </inertial>
      <visual name="link_2_visual">
        <geometry>
          <mesh>
            <uri>model://fanuc_m20i/meshes/m20ib25/visual/link_2.stl</uri>
          </mesh>
        </geometry>
        <material>
          <ambient>0.96 0.76 0.13 1.0</ambient>
          <diffuse>0.96 0.76 0.13 1.0</diffuse>
        </material>
      </visual>
      <collision name="link_2_collision">
        <geometry>
          <mesh>
            <uri>model://fanuc_m20i/meshes/m20ib25/collision/link_2.stl</uri>
          </mesh>
        </geometry>
      </collision>
    </link>

    <link name="link_3">
      <inertial>
        <mass>15.0</mass>
        <inertia>
          <ixx>1.0</ixx>
          <iyy>1.0</iyy>
          <izz>1.0</izz>
        </inertia>
      </inertial>
      <visual name="link_3_visual">
        <geometry>
          <mesh>
            <uri>model://fanuc_m20i/meshes/m20ib25/visual/link_3.stl</uri>
          </mesh>
        </geometry>
        <material>
          <ambient>0.96 0.76 0.13 1.0</ambient>
          <diffuse>0.96 0.76 0.13 1.0</diffuse>
        </material>
      </visual>
      <collision name="link_3_collision">
        <geometry>
          <mesh>
            <uri>model://fanuc_m20i/meshes/m20ib25/collision/link_3.stl</uri>
          </mesh>
        </geometry>
      </collision>
    </link>

    <link name="link_4">
      <inertial>
        <mass>10.0</mass>
        <inertia>
          <ixx>1.0</ixx>
          <iyy>1.0</iyy>
          <izz>1.0</izz>
        </inertia>
      </inertial>
      <visual name="link_4_visual">
        <geometry>
          <mesh>
            <uri>model://fanuc_m20i/meshes/m20ib25/visual/link_4.stl</uri>
          </mesh>
        </geometry>
        <material>
          <ambient>0.96 0.76 0.13 1.0</ambient>
          <diffuse>0.96 0.76 0.13 1.0</diffuse>
        </material>
      </visual>
      <collision name="link_4_collision">
        <geometry>
          <mesh>
            <uri>model://fanuc_m20i/meshes/m20ib25/collision/link_4.stl</uri>
          </mesh>
        </geometry>
      </collision>
    </link>

    <link name="link_5">
      <inertial>
        <mass>8.0</mass>
        <inertia>
          <ixx>1.0</ixx>
          <iyy>1.0</iyy>
          <izz>1.0</izz>
        </inertia>
      </inertial>
      <visual name="link_5_visual">
        <geometry>
          <mesh>
            <uri>model://fanuc_m20i/meshes/m20ib25/visual/link_5.stl</uri>
          </mesh>
        </geometry>
        <material>
          <ambient>0.96 0.76 0.13 1.0</ambient>
          <diffuse>0.96 0.76 0.13 1.0</diffuse>
        </material>
      </visual>
      <collision name="link_5_collision">
        <geometry>
          <mesh>
            <uri>model://fanuc_m20i/meshes/m20ib25/collision/link_5.stl</uri>
          </mesh>
        </geometry>
      </collision>
    </link>

    <link name="link_6">
      <inertial>
        <mass>5.0</mass>
        <inertia>
          <ixx>1.0</ixx>
          <iyy>1.0</iyy>
          <izz>1.0</izz>
        </inertia>
      </inertial>
      <visual name="link_6_visual">
        <geometry>
          <mesh>
            <uri>model://fanuc_m20i/meshes/m20ib25/visual/link_6.stl</uri>
          </mesh>
        </geometry>
        <material>
          <ambient>0.15 0.15 0.15 1.0</ambient>
          <diffuse>0.15 0.15 0.15 1.0</diffuse>
        </material>
      </visual>
      <collision name="link_6_collision">
        <geometry>
          <mesh>
            <uri>model://fanuc_m20i/meshes/m20ib25/collision/link_6.stl</uri>
          </mesh>
        </geometry>
      </collision>
    </link>

    <joint name="joint_1" type="revolute">
      <pose relative_to="base_link">0 0 0.650 0 0 0</pose>
      <parent>base_link</parent>
      <child>link_1</child>
      <axis>
        <xyz>0 0 1</xyz>
        <limit>
          <lower>-3.141592653589793</lower>
          <upper>3.141592653589793</upper>
          <effort>0</effort>
          <velocity>3.5779249665883754</velocity>
        </limit>
      </axis>
    </joint>

    <joint name="joint_2" type="revolute">
      <pose relative_to="link_1">0.075 0 0 0 0 0</pose>
      <parent>link_1</parent>
      <child>link_2</child>
      <axis>
        <xyz>0 1 0</xyz>
        <limit>
          <lower>-1.7453292519943295</lower>
          <upper>2.443460952792061</upper>
          <effort>0</effort>
          <velocity>3.5779249665883754</velocity>
        </limit>
      </axis>
    </joint>

    <joint name="joint_3" type="revolute">
      <pose relative_to="link_2">0 0 0.905 0 0 0</pose>
      <parent>link_2</parent>
      <child>link_3</child>
      <axis>
        <xyz>0 -1 0</xyz>
        <limit>
          <lower>-2.600540585471551</lower>
          <upper>5.585053606381854</upper>
          <effort>0</effort>
          <velocity>4.537856055185257</velocity>
        </limit>
      </axis>
    </joint>

    <joint name="joint_4" type="revolute">
      <pose relative_to="link_3">0 0 0.120 0 0 0</pose>
      <parent>link_3</parent>
      <child>link_4</child>
      <axis>
        <xyz>-1 0 0</xyz>
        <limit>
          <lower>-3.490658503988659</lower>
          <upper>3.490658503988659</upper>
          <effort>0</effort>
          <velocity>7.243116395776467</velocity>
        </limit>
      </axis>
    </joint>

    <joint name="joint_5" type="revolute">
      <pose relative_to="link_4">0.865 0 0 0 0 0</pose>
      <parent>link_4</parent>
      <child>link_5</child>
      <axis>
        <xyz>0 -1 0</xyz>
        <limit>
          <lower>-2.530727415391778</lower>
          <upper>2.530727415391778</upper>
          <effort>0</effort>
          <velocity>7.243116395776467</velocity>
        </limit>
      </axis>
    </joint>

    <joint name="joint_6" type="revolute">
      <pose relative_to="link_5">0.100 0 0 0 0 0</pose>
      <parent>link_5</parent>
      <child>link_6</child>
      <axis>
        <xyz>-1 0 0</xyz>
        <limit>
          <lower>-4.71238898038469</lower>
          <upper>4.71238898038469</upper>
          <effort>0</effort>
          <velocity>15.3588974175501</velocity>
        </limit>
      </axis>
    </joint>

    <link name="base"/>
    <joint name="base_link_base" type="fixed">
      <pose relative_to="base_link">0 0 0.650 0 0 0</pose>
      <parent>base_link</parent>
      <child>base</child>
    </joint>

    <link name="flange"/>
    <joint name="joint_6_flange" type="fixed">
      <pose relative_to="link_6">0 0 0 0 0 0</pose>
      <parent>link_6</parent>
      <child>flange</child>
    </joint>

    <link name="tool0">
      <inertial>
        <mass>0.1</mass>
        <inertia>
          <ixx>0.001</ixx>
          <iyy>0.001</iyy>
          <izz>0.001</izz>
        </inertia>
      </inertial>
    </link>
    <joint name="link_6_tool0" type="fixed">
      <pose relative_to="flange">0 0 0 3.141592653589793 -1.5707963267948966 0</pose>
      <parent>flange</parent>
      <child>tool0</child>
    </joint>

    <link name="camera_mount">
      <inertial>
        <mass>0.05</mass>
        <inertia>
          <ixx>0.001</ixx>
          <iyy>0.001</iyy>
          <izz>0.001</izz>
        </inertia>
      </inertial>
      <collision name="camera_mount_collision">
        <geometry>
          <box>
            <size>0.08 0.08 0.08</size>
          </box>
        </geometry>
      </collision>
      <visual name="camera_mount_visual">
        <geometry>
          <box>
            <size>0.08 0.08 0.08</size>
          </box>
        </geometry>
        <material>
          <ambient>0.1 0.5 0.7 1.0</ambient>
          <diffuse>0.15 0.65 0.85 1.0</diffuse>
        </material>
      </visual>

      <sensor name="pool_camera_2d" type="camera">
        <pose>0 0 0 0 0 0</pose>
        <camera>
          <horizontal_fov>1.047</horizontal_fov>
          <image>
            <width>640</width>
            <height>480</height>
            <format>R8G8B8</format>
          </image>
          <clip>
            <near>0.1</near>
            <far>100.0</far>
          </clip>
        </camera>
        <always_on>1</always_on>
        <update_rate>30</update_rate>
        <visualize>1</visualize>
        <plugin name="ros_gz_pool_camera_plugin" filename="libros_gz_camera.so">
          <ros_topic>/image_topic</ros_topic>
          <frame_name>camera_mount</frame_name>
          <qos>sensor_default</qos>
        </plugin>
      </sensor>

      <sensor name="line_scan_3d" type="depth">
        <pose>0 0 0 0 0 0</pose>
        <depth>
          <format>Z16</format>
          <clip>
            <near>0.1</near>
            <far>30.0</far>
          </clip>
        </depth>
        <always_on>1</always_on>
        <update_rate>15</update_rate>
        <visualize>0</visualize>
        <plugin name="ros_gz_line_scan_plugin" filename="libros_gz_depth_camera.so">
          <ros_topic>/tcp_depth_image</ros_topic>
          <pointcloud_topic>/tcp_cloud_raw</pointcloud_topic>
          <frame_name>camera_mount</frame_name>
          <qos>sensor_default</qos>
        </plugin>
      </sensor>
    </link>

    <joint name="tool0_camera_mount" type="fixed">
      <pose relative_to="tool0">0.04 0 0.13 0 0 0</pose>
      <parent>tool0</parent>
      <child>camera_mount</child>
    </joint>
  </model>
</sdf>
